Workbook
Name ComplejidadEstimación: Sheet1!$B$3:$B$5

Sheet Data maestra
A2: Estimación por complejidad | B2: días calendario
A3: Alta | B3: 28
A4: Media | B4: 14
A5: Baja | B5: 7

Sheet Criterios de priorización
A2: Columna | B2: Criterio nuevo | C2: Descripción general | D2: Peso | E2: Descripción del nivel | F2: Puntaje
A3: Proyecto SPO | B3: Proyectos de la SPO | C3: Proyecto que forma parte de la SPO | D3: 0.3 | E3: Si | F3: 5
E4: No | F4: 0
A5: Tipo de iniciativa | B5: Tipo de iniciativa | C5: Evalúa si es una iniciativa normativa, lega , seguridad Ti, etc | D5: 0.3 | E5: Regulatoria | F5: 5
E6: Seguridad TI | F6: 3
E7: ITSM | F7: 3
E8: Otros | F8: 1
A9: Beneficio cuantitativo (anual) | B9: Beneficio cuantitativo esperado | C9: Mide el valor que genera la atención de la necesidad del negocio (Falta indicar en cuanto tiempo) | D9: 0.15 | E9: Mayor a S/500,000.00 | F9: 5
E10: Entre S/100,000.00 y S/500,000.00 | F10: 3
E11: Menor a S/100,000.00 | F11: 2
E12: No cuantificado o S/0 | F12: 1
A13: Pilar estratégico | B13: Alineación estratégica | C13: Mide el impacto en los pilares estratégicos de la organización. | D13: 0.1 | E13: Crecimiento escalable | F13: 5
E14: Excelencia académica | F14: 5
E15: Experiencia | F15: 4
E16: Student Success y Empleabilidad | F16: 4
E17: Excelencia operativa | F17: 3
E18: Ninguno | F18: 0
A19: Usuarios beneficiados1 | B19: Usuarios beneficiados | C19: Mide impacto en los usuarios que serán beneficiados por la iniciativa | D19: 0.15 | E19: Alumnos | F19: 5
E20: Todos | F20: 5
E21: Docentes | F21: 4
E22: Administrativos | F22: 1
D23: =SUM(D3:D20) -> 1

Sheet Resumen
B1: POR ESTIMAR | E1: POR APROBAR ESTIMACION | H1: POR HABILITAR PPTO | K1: POR PLANIFICAR
B2: Líder de Dominio | C2: TOTAL Iniciativas | E2: IT BP | F2: TOTAL Iniciativas | H2: IT BP | I2: TOTAL Iniciativas | K2: Líder de Dominio | L2: TOTAL Iniciativas
B3: Aaron Melgar | C3: 4 | E3: Bruno Chiappe | F3: 2 | H3: Ángela Lucano | I3: 1 | K3: Alan Medina | L3: 1
B4: Ana Rojas | C4: 2 | E4: Carla Arias-Schreiber | F4: 5 | H4: Bruno Chiappe | I4: 1 | K4: Ana Rojas | L4: 1
B5: Ana Vega | C5: 9 | E5: Franco Vera | F5: 2 | H5: Carla Arias-Schreiber | I5: 2 | K5: Ana Vega | L5: 1
B6: Carmen Cruz | C6: 4 | E6: Gerson Vereau | F6: 1 | H6: Franco Vera | I6: 5 | K6: César Soplín | L6: 1
B7: César Soplín | C7: 17 | E7: José Paredes | F7: 3 | H7: Gerson Vereau | I7: 2 | K7: Elmer Zapata | L7: 1
B8: Cristina Andonaire | C8: 1 | E8: Total general | F8: 13 | H8: José Paredes | I8: 1 | K8: Hugo Paucar | L8: 1
B9: Cristy Vargas | C9: 1 | H9: Total general | I9: 12 | K9: Luis Calderón | L9: 1
B10: Elmer Zapata | C10: 9 | K10: Nicolas Morales | L10: 1
B11: Enrique Ruiz Huidobro | C11: 1 | K11: Nohelí Cabrera | L11: 1
B12: Hugo Vega | C12: 7 | K12: Total general | L12: 9
B13: Ivan Rengifo | C13: 2
B14: Janny Nicasio | C14: 1
B15: Johnnel Ayala | C15: 2
B16: Johnny Rodriguez | C16: 2
B17: Nicolas Morales | C17: 14
B18: Nohelí Cabrera | C18: 2
B19: Pendiente LD | C19: 3
B20: Rolando Lopez | C20: 1
B21: Ruddy Pereda | C21: 3
B22: Tania Tamariz | C22: 1
B23: Total general | C23: 86

Sheet BD
A1: Id | B1: Hora de inicio | C1: Hora de finalización | D1: Correo electrónico | E1: Nombre | F1: Título de la INICIATIVA | G1: Objetivo | H1: Institución | I1: VP del área solicitante | J1: Usuario solicitante del negocio | K1: Aprobación de la iniciativa por el VP o Director | L1: IT BP | M1: Fecha de entrega requerida | N1: Proyecto SPO | O1: Workstream del proyecto SPO | P1: ID SPO | Q1: Tipo de iniciativa | R1: Descripción del problema o desafío | S1: Situación deseada | T1: Procesos y áreas impactadas | U1: Usuarios beneficiados1 | V1: Pilar estratégico | W1: Forma parte de la estabilización de procesos SIS | X1: Beneficio cuantitativo (anual) | Y1: Beneficios cualitativos | Z1: Adjuntar ppt de la iniciativa | AA1: Puntaje sugerido
A2: =[1]Sheet1!A2 -> 15 | B2: =[1]Sheet1!B2 -> 46006.494 | C2: =[1]Sheet1!C2 -> 46008.703 | D2: =[1]Sheet1!D2 -> luis.almeyda@upc.pe | E2: =[1]Sheet1!E2 -> Luis Alberto Almeyda Porras | F2: =[1]Sheet1!F2 -> Mejoras en SPRING - Facturación por nuevo registro de Ventas SIRE | G2: =[1]Sheet1!G2 -> Necesitamos asegurar el envío correcto del 100% de información para el registro de Ventas a SUNAT en Boletas, Facturas, Notas de Crédito y Débito, dado que actualmente se tienen 2 casuísticas que generan incidencias en el reporte y por ende existen observaciones por parte de SUNAT. - Existen saltos en correlativos de las Notas de Crédito y Nota de Débito que generan inconsistencia en la información. - Se ha detectado que la fecha de emisión de las Notas de Crédito y Nota de Débito se generan con una fecha anterior al comprobante fiscal (Factura o Boleta). | H2: =[1]Sheet1!H2 -> UPC | ... AA2: =[1]Sheet1!AA2 -> 2.4
A3: =[1]Sheet1!A3 -> 16 | B3: =[1]Sheet1!B3 -> 46036.44 | C3: =[1]Sheet1!C3 -> 46036.443 | D3: =[1]Sheet1!D3 -> giancarlo.villacorta@upc.pe | E3: =[1]Sheet1!E3 -> Giancarlo Villacorta Quiñones | F3: =[1]Sheet1!F3 -> Mejoras en trámites de retiro de ciclo | G3: =[1]Sheet1!G3 -> Necesitamos que el tramite de retiro de ciclo valide la vigencia de la carta de permanencia durante el periodo actual para que solo considere en el periodo que corresponde, además que el alumno EPE pueda registrar aún si cuenta con notas o haya cursado el módulo A; Para evitar gestiones manuales por falta de recursos / evitar reclamos hacia la universidad o a través de indecopi; logrando que todas las solucitudes de alumnos se registren por el trámite | H3: =[1]Sheet1!H3 -> UPC | ... AA3: =[1]Sheet1!AA3 -> 0.3
A4: =[1]Sheet1!A4 -> 22 | B4: =[1]Sheet1!B4 -> 46042.586 | C4: =[1]Sheet1!C4 -> 46042.665 | D4: =[1]Sheet1!D4 -> alejandro.tello@laureate.pe | E4: =[1]Sheet1!E4 -> Alejandro Tello Llosa | F4: =[1]Sheet1!F4 -> Requerimiento de servicios de CRM para el desarrollo de la plataforma de Admisión Online | G4: =[1]Sheet1!G4 -> Necesitamos la creación de Servicios de integración con CRM para que realicemos las integraciones necesarias en la nueva plataforma de admisión Online logrando implementar una plataforma digital que permita reducir la deserción en las etapas previas a la matrícula, interviniendo en el momento de mayor intención del postulante. | H4: =[1]Sheet1!H4 -> UPN | ... Q4: =[1]Sheet1!Q4 -> Otro | S4: =[1]Sheet1!S4 -> 0 | T4: =[1]Sheet1!T4 -> Proceso de Admisión | U4: =[1]Sheet1!U4 -> 0 | V4: =[1]Sheet1!V4 -> Transformación Digital | W4: =[1]Sheet1!W4 -> No | X4: =[1]Sheet1!X4 -> 0 | Y4: =[1]Sheet1!Y4 -> Mejorar la experiencia del prospecto, reducir la operatividad del equipo de admisión, reducción los tiempos de matrícula en al menos 48 hrs | Z4: =[1]Sheet1!Z4 -> https://educorpperu-my.sharepoint.com/personal/diana_zapata_laureate_pe1/Documents/Aplicaciones/Microsoft%20Forms/REGISTRO%20DE%20INICIATIVAS/Pregunta/funnel-de-desercion-carreras-a-distancia-UPN_Alejandro%20Tello%20Llos.png | AA4: =[1]Sheet1!AA4 -> 1.5
A5: =[1]Sheet1!A5 -> 23 | B5: =[1]Sheet1!B5 -> 46042.744 | C5: =[1]Sheet1!C5 -> 46042.76 | D5: =[1]Sheet1!D5 -> luis.almeyda@upc.pe | E5: =[1]Sheet1!E5 -> Luis Alberto Almeyda Porras | F5: =[1]Sheet1!F5 -> Reporte para Seguimiento de Retiros de Ciclo formales | G5: =[1]Sheet1!G5 -> Se requiere según el control ejecutar una validación al 100% de los retiros formales del mes para alumnos de pregrado y EPE en los ciclos de verano y regulares, actualmente no se cuenta con un reporte que permita hacer esta validación, por lo que la revisión del equipo de facturación realiza es muestral (5% de los retiros mensuales). El promedio entre 2024 y 2025 de retiros formales ascendió a 3.7M USD. | H5: =[1]Sheet1!H5 -> UPC | ... AA5: =[1]Sheet1!AA5 -> 1.2
A6: =[1]Sheet1!A6 -> 24 | B6: =[1]Sheet1!B6 -> 46043.469 | C6: =[1]Sheet1!C6 -> 46043.537 | D6: =[1]Sheet1!D6 -> liz.medina@upc.pe | E6: =[1]Sheet1!E6 -> Carolina Medina Suarez | F6: =[1]Sheet1!F6 -> Mejora del Reporte de Matriculados de Licencias Coursera | G6: =[1]Sheet1!G6 -> Necesitamos optimizar el reporte de matriculados de licencias Coursera reduciendo el tiempo de carga de 25-30 minutos a máximo 5 minutos y habilitando la funcionalidad de descarga, para que el equipo pueda monitorear y gestionar las 28,000 licencias Coursera de forma oportuna durante el periodo de matrícula, logrando maximizar el uso de licencias, recuperar aproximadamente 450 licencias por ciclo de alumnos retirados (ahorro estimado de $22,500 USD), y permitir la toma de decisiones en tiempo casi real para la reasignación eficiente de recursos. | H6: =[1]Sheet1!H6 -> UPC | ... AA6: =[1]Sheet1!AA6 -> 0.3
A7: =[1]Sheet1!A7 -> 25 | B7: =[1]Sheet1!B7 -> 46048.588 | C7: =[1]Sheet1!C7 -> 46048.615 | D7: =[1]Sheet1!D7 -> makarena.ramos@laureate.pe | E7: =[1]Sheet1!E7 -> Makarena Ramos Aleman | F7: =[1]Sheet1!F7 -> Modificación de MDUU de elegibles en Banner. | G7: =[1]Sheet1!G7 -> [SPO] Se requiere mejora de MDUU de asignación de elegibles, que considere cambios aplicados en las marcas de Suspensión y Baja académica. Para asegurar la correcta asignación de los elegibles, excluyendo a los estudiantes que han sido suspendidos temporalmente. Logrando que los alumnos desaprobados por tercera vez tengan la posibilidad de retornar el siguiente ciclo. | H7: =[1]Sheet1!H7 -> UPN | ... AA7: =[1]Sheet1!AA7 -> 0.5
A8: =[1]Sheet1!A8 -> 26 | B8: =[1]Sheet1!B8 -> 46048.615 | C8: =[1]Sheet1!C8 -> 46048.624 | D8: =[1]Sheet1!D8 -> makarena.ramos@laureate.pe | E8: =[1]Sheet1!E8 -> Makarena Ramos Aleman | F8: =[1]Sheet1!F8 -> Actualización de Reportes PF012 y AC006 -Penalidad por 4to curso repetido | G8: =[1]Sheet1!G8 -> [SPO]Necesitamos la actualización de los reportes para que pueda incluir la Validación de carga de las penalidades(PF012), Cierre de Campaña - AC006. Logrando que incluya la casuistica de las penalidades por 4ta en los controles SOX. | H8: =[1]Sheet1!H8 -> UPN | ... AA8: =[1]Sheet1!AA8 -> 0.5
A9: =[1]Sheet1!A9 -> 27 | B9: =[1]Sheet1!B9 -> 46048.633 | C9: =[1]Sheet1!C9 -> 46048.649 | D9: =[1]Sheet1!D9 -> makarena.ramos@laureate.pe | E9: =[1]Sheet1!E9 -> Makarena Ramos Aleman | F9: =[1]Sheet1!F9 -> Mejora en la estimación de penalidades – 4ta repitencia. | G9: =[1]Sheet1!G9 -> [SPO]Mejora del proceso de estimación de penalidad para que genere los cargos con penalidad por cuarta repitencia. Logrando que los alumnos puedan matricularse nuevamente pagando la penalidad correspondiente. | H9: =[1]Sheet1!H9 -> UPN | ... AA9: =[1]Sheet1!AA9 -> 1.4
A10: =[1]Sheet1!A10 -> 28 | B10: =[1]Sheet1!B10 -> 46048.633 | C10: =[1]Sheet1!C10 -> 46048.654 | D10: =[1]Sheet1!D10 -> makarena.ramos@laureate.pe | E10: =[1]Sheet1!E10 -> Makarena Ramos Aleman | F10: =[1]Sheet1!F10 -> Marcación de reingresantes desaprobados por tercera vez (4TAV) | G10: =[1]Sheet1!G10 -> [SPO]Mejorar el proceso de marcación de 3ra repitencia durante el proceso de Reingresos para incluir a los alumnos con 4ta repitencia (reingresos). Esto está vinculado a la ejecución de la decisión de admisión 35.Logrando la automatización en el proceso de reingresos para los de 4ta. | H10: =[1]Sheet1!H10 -> UPN | ... AA10: =[1]Sheet1!AA10 -> 0.5
A11: =[1]Sheet1!A11 -> 29 | B11: =[1]Sheet1!B11 -> 46048.633 | C11: =[1]Sheet1!C11 -> 46048.662 | D11: =[1]Sheet1!D11 -> makarena.ramos@laureate.pe | E11: =[1]Sheet1!E11 -> Makarena Ramos Aleman | F11: =[1]Sheet1!F11 -> Proyección automática de cursos por 4ta vez | G11: =[1]Sheet1!G11 -> Necesitamos contar con un proceso que proyecte de forma automática únicamente a cursos por cuarta matrícula del alumno, para que luego este pueda hacer su matricula en línea de dicho curso: - Reingreso (uno a uno). Logrando que el alumno pueda realizar su matricula de manera satisfactoria en el tiempo establecido. | H11: =[1]Sheet1!H11 -> UPN | ... AA11: =[1]Sheet1!AA11 -> 1.4
A12: =[1]Sheet1!A12 -> 30 | B12: =[1]Sheet1!B12 -> 46048.651 | C12: =[1]Sheet1!C12 -> 46048.669 | D12: =[1]Sheet1!D12 -> gerson.vereau@upn.edu.pe | E12: =[1]Sheet1!E12 -> Gerson Vereau Rosas | F12: =[1]Sheet1!F12 -> Franja horaria no visible para horas adicionales | G12: =[1]Sheet1!G12 -> Establecer en Banner que las franjas horarias de madrugada (00:00 a.m. – 06:00 a.m.) no sean visibles en la plataforma del estudiante. Además, cuando un docente registre su marcación en una franja distinta a la mencionada (es decir, fuera de 00:00 a.m. – 06:00 a.m.), la franja de madrugada debe marcarse automáticamente y viajen para pago ambas franjas horarias | H12: =[1]Sheet1!H12 -> UPN | ... AA12: =[1]Sheet1!AA12 -> 0.3
A13: =[1]Sheet1!A13 -> 31 | B13: =[1]Sheet1!B13 -> 46048.646 | C13: =[1]Sheet1!C13 -> 46048.673 | D13: =[1]Sheet1!D13 -> jose.herbozo@upn.edu.pe | E13: =[1]Sheet1!E13 -> Jose Paredes Herbozo | F13: =[1]Sheet1!F13 -> Incorporar sección de "variable étnica" a la Ficha de Postulación y CRM | G13: =[1]Sheet1!G13 -> SUNEDU requiere que los alumnos de Pregrado, Posgrado (no cursos cortos, no diplomados) dejen registro de 2 preguntas: 1. El postulante por sus costumbres y antepasados se siente parte de: (alternativas pre cargadas) 2. El postulante habla alguna lengua indígena u originaria: (alternativas pre cargadas) Esto con el fin de poder registrar en la BD de SUNEDU la demografía de los estudiantes con fines propios del estado. El equipo Legal y Académico han requerido que UPN sea la universidad piloto para esta disposición de SUNEDU | H13: =[1]Sheet1!H13 -> UPN | ... AA13: =[1]Sheet1!AA13 -> 1.8
A14: =[1]Sheet1!A14 -> 32 | B14: =[1]Sheet1!B14 -> 46048.673 | C14: =[1]Sheet1!C14 -> 46048.69 | D14: =[1]Sheet1!D14 -> jose.herbozo@upn.edu.pe | E14: =[1]Sheet1!E14 -> Jose Paredes Herbozo | F14: =[1]Sheet1!F14 -> Desactivación del proceso automático de reembolsos en el retiro formal | G14: =[1]Sheet1!G14 -> Necesitamos desactivar el proceso automático de reembolsos del retiro formal, para que se deje de generar notas de crédito, notas de débito y envíos erróneos a cuentas por pagar y tesorería, logrando evitar reprocesos, pagos indebidos y carga operativa en las áreas afectadas. | H14: =[1]Sheet1!H14 -> UPN | ... AA14: =[1]Sheet1!AA14 -> 0.3
A15: =[1]Sheet1!A15 -> 33 | B15: =[1]Sheet1!B15 -> 46049.461 | C15: =[1]Sheet1!C15 -> 46049.472 | D15: =[1]Sheet1!D15 -> daniella.poppe@laureate.pe | E15: =[1]Sheet1!E15 -> Daniella Poppe Medina | F15: =[1]Sheet1!F15 -> Lead Scoring - Integración de modelo Lead Scoring a CRM | G15: =[1]Sheet1!G15 -> Necesitamos integrar el Lead Scoring al CRM para que el equipo comercial pueda priorizar de manera más efectiva los leads que recibe para la venta logrando un ratio de conversión mayor. | H15: =[1]Sheet1!H15 -> UPN | ... AA15: =[1]Sheet1!AA15 -> 1.8
A16: =[1]Sheet1!A16 -> 34 | B16: =[1]Sheet1!B16 -> 46049.599 | C16: =[1]Sheet1!C16 -> 46049.717 | D16: =[1]Sheet1!D16 -> eduardo.paul@cibertec.pe | E16: =[1]Sheet1!E16 -> Eduardo Paul Aguilar | F16: =[1]Sheet1!F16 -> Actualización en Gestión Docente sobre cambios realizados en Banner | G16: =[1]Sheet1!G16 -> Necesitamos incluir en el proceso de sincronización de datos de Banner hacia Gestión docente, aquellos cambios de sección que ocurre en Banner y que no son reflejados en Gestión docente para que se eviten registros duplicados en el sistema y registros faltantes logrando validación de datos por parte de docente, eliminación de ticket por este escenario. | H16: =[1]Sheet1!H16 -> CIB | ... AA16: =[1]Sheet1!AA16 -> 0.3
... A367: =[1]Sheet1!A367 -> 397 | B367: =[1]Sheet1!B367 -> 46287.75 | C367: =[1]Sheet1!C367 -> 46287.762 | D367: =[1]Sheet1!D367 -> anthony.lazaro@laureate.pe | E367: =[1]Sheet1!E367 -> Anthony Adrian Lazaro Espadin | F367: =[1]Sheet1!F367 -> Automatización de Autorización de acceso a Bases de DP | G367: =[1]Sheet1!G367 -> Necesitamos automatizar y centralizar la gestión de solicitudes de acceso a base de datos, para eliminar la gestión manual mediante correos y asegurar un flujo estandarizado de validación, aprobación y atención de requerimientos, logrando mayor trazabilidad, control de conformidades, reducción de tiempos de atención y una mejor experiencia para los usuarios. | H367: =[1]Sheet1!H367 -> CORP | ... AA367: =[1]Sheet1!AA367 -> 0.6
A368: =[1]Sheet1!A368 -> 0

Sheet BD New
A1: Id | B1: Hora de inicio | C1: Hora de finalización | D1: Correo electrónico | E1: Nombre | F1: Título de la INICIATIVA | G1: Objetivo | H1: Institución | I1: VP del área solicitante | J1: Usuario solicitante del negocio | K1: Aprobación de la iniciativa por el VP o Director | L1: IT BP | M1: Fecha de entrega requerida | N1: Proyecto SPO | O1: Workstream del proyecto SPO | P1: ID SPO | Q1: Tipo de iniciativa | R1: Descripción del problema o desafío | S1: Situación deseada | T1: Procesos y áreas impactadas | U1: Usuarios beneficiados1 | V1: Pilar estratégico | W1: Forma parte de la estabilización de procesos SIS | X1: Beneficio cuantitativo (anual) | Y1: Beneficios cualitativos | Z1: Adjuntar ppt de la iniciativa | AA1: Puntaje sugerido
A2: =IF([2]Sheet1!A3="","",[2]Sheet1!A3+399) -> 401 | B2: =[2]Sheet1!B3 -> 46289.379 | C2: =[2]Sheet1!C3 -> 46289.393 | D2: =[2]Sheet1!D3 -> bruno.chiappe@laureate.pe | E2: =[2]Sheet1!E3 -> Bruno Chiappe Vegas | F2: =[2]Sheet1!F3 -> Automatización de carga de llamadas de Genesys a CRM Cibertec | G2: =[2]Sheet1!G3 -> Necesitamos automatizar la carga de información de llamadas de Genesys hacia CRM Cibertec, para eliminar la ejecución manual y recurrente de cargas masivas que actualmente requiere intervención de especialistas y está sujeta a errores y retrasos, logrando disponer de la información oportunamente para el negocio, reducir la carga operativa del equipo TI y disminuir la necesidad de pases Express asociados a estas cargas. | H2: =[2]Sheet1!H3 -> CIB | I2: =[2]Sheet1!I3 -> Humberto Marotta - Tecnologías y transformación digital | ... AA2: =[2]Sheet1!AA3 -> 0.6
A3: =IF([2]Sheet1!A4="","",[2]Sheet1!A4+399) -> 402 | B3: =[2]Sheet1!B4 -> 46289.48 | C3: =[2]Sheet1!C4 -> 46289.501 | D3: =[2]Sheet1!D4 -> alejandra.beraun@laureate.pe | E3: =[2]Sheet1!E4 -> Alejandra Beraun Ching | F3: =[2]Sheet1!F4 -> Proyecto Cultura y Espacios | G3: =[2]Sheet1!G4 -> Implementar una nueva aplicacion de reservas que mejore la gestión de asignación de salas y que esté correctamente distribuida para el personal administrativo. Para lo cual se está rediseñando el piso 26, de manera que la aplicación converse con el nuevo espacio. | H3: =[2]Sheet1!H4 -> LAU | I3: =[2]Sheet1!I4 -> Álvaro Valdez - VP Operaciones | ... AA3: =[2]Sheet1!AA4 -> 0.7
A4: =IF([2]Sheet1!A5="","",[2]Sheet1!A5+399) -> 403 | B4: =[2]Sheet1!B5 -> 46289.51 | C4: =[2]Sheet1!C5 -> 46289.537 | D4: =[2]Sheet1!D5 -> suly.kong@upn.edu.pe | E4: =[2]Sheet1!E5 -> Suly Kong Paredes | F4: =[2]Sheet1!F5 -> La Defensoría tiene sobrecarga por atención unipersonal y desinformación de los usuarios, quienes acuden de forma presencial por trámites ajenos a sus funciones. La falta de un filtro digital previo genera atenciones prolongadas y dificulta organizar los expedientes con sustento desde el inicio. | G4: =[2]Sheet1!G5 -> Proporcionar a la comunidad universitaria (estudiantes, egresados, docentes y colaboradores) un canal digital estructurado, accesible y confidencial para canalizar petitorios, consultas y denuncias, estandarizando los requisitos desde el origen para optimizar los tiempos de respuesta y asegurar la correcta derivación institucional. | H4: =[2]Sheet1!H5 -> UPN | I4: =[2]Sheet1!I5 -> Martín Santana - Rectorado UPN | ... AA4: =[2]Sheet1!AA5 -> 2.7
A5: =IF([2]Sheet1!A6="","",[2]Sheet1!A6+399) -> 404 | B5: =[2]Sheet1!B6 -> 46290.496 | C5: =[2]Sheet1!C6 -> 46290.509 | D5: =[2]Sheet1!D6 -> brenda.maguina@laureate.pe | E5: =[2]Sheet1!E6 -> Brenda Michelle Maguiña Delgadillo | F5: =[2]Sheet1!F6 -> Implementación de Reloj Fisico-Personal Fiscalizado Presencial. | G5: =[2]Sheet1!G6 -> Necesitamos asegurar que el colaborador deberá realizar su marcación al llegar físicamente a las instalaciones de todas las instituciones inlcuyendo LCT. El registro quedará asociado al marcador y será integrado con el sistema HCM, con veracidad. | H5: =[2]Sheet1!H6 -> CORP | I5: =[2]Sheet1!I6 -> Tairi Ruillier- VP Personas y Cultura | ... AA5: =[2]Sheet1!AA6 -> 0.7
A6: =IF([2]Sheet1!A7="","",[2]Sheet1!A7+399) -> 405 | B6: =[2]Sheet1!B7 -> 46290.505 | C6: =[2]Sheet1!C7 -> 46290.536 | D6: =[2]Sheet1!D7 -> miguel.puccio@upn.edu.pe | E6: =[2]Sheet1!E7 -> Miguel Puccio Wendorff | F6: =[2]Sheet1!F7 -> Configuracion de apertura de beneficios de admisión | G6: =[2]Sheet1!G7 -> - Modificación del calculo sobre el beneficio mayor - Recalculo sobre más de una línea de beneficio - Visualización de los distintos beneficios que se ofrece a alumno en las boletas, detallando cada beneficio en una linea independiente - Creación de tabla intermedia para homologación de categorías | H6: =[2]Sheet1!H7 -> UPC | I6: =[2]Sheet1!I7 -> Alex Pendavis - VP Finanzas | ... AA6: =[2]Sheet1!AA7 -> 1.2
A7: =IF([2]Sheet1!A8="","",[2]Sheet1!A8+399) -> 406 | B7: =[2]Sheet1!B8 -> 46291.414 | C7: =[2]Sheet1!C8 -> 46291.449 | D7: =[2]Sheet1!D8 -> franco.vera@laureate.pe | E7: =[2]Sheet1!E8 -> Franco Manuel Vera Sanchez | F7: =[2]Sheet1!F8 -> LEAN+IA: CALIDAD | G7: =[2]Sheet1!G8 -> Estimar componentes fuera de desarrollo (licencias, almacenamiento, integraciones, etc) para repotenciar, agilizar, simplificar y estandarizar el flujo end-to-end de la gestión integral de aseguramiento de la calidad, apalancando en la Inteligencia Artificial y otras tecnologías como aliadas estratégicas, de tal forma que logremos liberar al equipo de las carga operativa y manual para que puedan enfocar su verdadero talento en actividades de alto valor, análisis estratégico y mejora continua, repotenciando su rol. | H7: =[2]Sheet1!H8 -> CORP | I7: =[2]Sheet1!I8 -> Joaquín Uribarri - VP Academia CIB | ... AA7: =[2]Sheet1!AA8 -> 0.6
A8: =IF([2]Sheet1!A9="","",[2]Sheet1!A9+399) -> 407 | B8: =[2]Sheet1!B9 -> 46292.883 | C8: =[2]Sheet1!C9 -> 46292.893 | D8: =[2]Sheet1!D9 -> percy.romero@laureate.pe | E8: =[2]Sheet1!E9 -> Percy Romero Vegas | F8: =[2]Sheet1!F9 -> APLICATIVO DE CONCILIACION MEDIOS DE PAGO - CIBERTEC | G8: =[2]Sheet1!G9 -> Implementar una herramienta de conciliación automática de medios de pago, que permita integrar y validar diariamente las transacciones provenientes de BCP, Interbank, Scotiabank, BBVA y Niubiz, u otro medio de pago comparándolas contra los registos del sistema Spring Comercial de CIB (tal como lo tiene UPC). | H8: =[2]Sheet1!H9 -> CIB | I8: =[2]Sheet1!I9 -> Alex Pendavis - VP Finanzas | ... AA8: =[2]Sheet1!AA9 -> 1.9
A9: =IF([2]Sheet1!A10="","",[2]Sheet1!A10+399) -> 408 | B9: =[2]Sheet1!B10 -> 46293.341 | C9: =[2]Sheet1!C10 -> 46293.352 | D9: =[2]Sheet1!D10 -> luis.calderon@laureate.pe | E9: =[2]Sheet1!E10 -> Luis Calderon Rodriguez | F9: =[2]Sheet1!F10 -> Upgrade y modernización de Jobs Batch UPN | G9: =[2]Sheet1!G10 -> Necesitamos actualizar y modernizar los jobs batch de UPN, para habilitar su migración y distribución en la nueva infraestructura, logrando reducir riesgos tecnológicos y mejorar la estabilidad y continuidad operativa de los procesos que soportan. | H9: =[2]Sheet1!H10 -> UPN | I9: =[2]Sheet1!I10 -> Humberto Marotta - Tecnologías y transformación digital | ... AA9: =[2]Sheet1!AA10 -> 1.5
A10: =IF([2]Sheet1!A11="","",[2]Sheet1!A11+399) -> 409 | B10: =[2]Sheet1!B11 -> 46294.377 | C10: =[2]Sheet1!C11 -> 46294.38 | D10: =[2]Sheet1!D11 -> angela.lucano@laureate.pe | E10: =[2]Sheet1!E11 -> Angela Lucano Carranza | F10: =[2]Sheet1!F11 -> Adecuación del Reporte de Retiro de Oficio UPC a la nueva normativa académica 2026 | G10: =[2]Sheet1!G11 -> Necesitamos adecuar el reporte de Retiro de Oficio vigente para alinearlo con la nueva normativa académica UPC, logrando una identificación automática, precisa y oportuna de estudiantes sujetos a retiro de oficio, asegurando el cumplimiento regulatorio y la continuidad del proceso académico dentro de los plazos establecidos para noviembre 2026. | H10: =[2]Sheet1!H11 -> UPC | I10: =[2]Sheet1!I11 -> Milagros Morgan - Rectorado UPC | ... AA10: =[2]Sheet1!AA11 -> 2.25
A11: =IF([2]Sheet1!A12="","",[2]Sheet1!A12+399) -> 410 | B11: =[2]Sheet1!B12 -> 46294.694 | C11: =[2]Sheet1!C12 -> 46294.705 | D11: =[2]Sheet1!D12 -> angela.lucano@laureate.pe | E11: =[2]Sheet1!E12 -> Angela Lucano Carranza | F11: =[2]Sheet1!F12 -> UPC: Adecuación de sistemas periféricos para soportar las nuevas mallas curriculares 2027 | G11: =[2]Sheet1!G12 -> Necesitamos adecuar los sistemas periféricos que consumen información académica de Banner para soportar correctamente el versionamiento de mallas curriculares, logrando que estudiantes, docentes y áreas administrativas visualicen información académica correcta y consistente en todos los sistemas. | H11: =[2]Sheet1!H12 -> UPC | I11: =[2]Sheet1!I12 -> Milagros Morgan - Rectorado UPC | ... AA11: =[2]Sheet1!AA12 -> 2.7
A12: =IF([2]Sheet1!A13="","",[2]Sheet1!A13+399) -> 411 | B12: =[2]Sheet1!B13 -> 46294.395 | C12: =[2]Sheet1!C13 -> 46295.15 | D12: =[2]Sheet1!D13 -> miriam.marca@laureate.pe | E12: =[2]Sheet1!E13 -> Miriam Marca Delgado | F12: =[2]Sheet1!F13 -> Aprovisionamiento Alumnos Nuevos y Administrativos | G12: =[2]Sheet1!G13 -> Necesitamos que el proceso de aprovisionamiento de cuentas de alumnos para CIBERTEC y UPC sea adoptado del modelo que tiene UPN | H12: =[2]Sheet1!H13 -> LAU | I12: =[2]Sheet1!I13 -> Humberto Marotta - Tecnologías y transformación digital | ... AA12: =[2]Sheet1!AA13 -> 2.1
A13: =IF([2]Sheet1!A14="","",[2]Sheet1!A14+399) -> 412 | B13: =[2]Sheet1!B14 -> 46295.79 | C13: =[2]Sheet1!C14 -> 46295.793 | D13: =[2]Sheet1!D14 -> jose.herbozo@laureate.pe | E13: =[2]Sheet1!E14 -> José Paredes Herbozo | F13: =[2]Sheet1!F14 -> Actualización del Reporte 01 GDO digital doc pendiente | G13: =[2]Sheet1!G14 -> Necesitamos actualizar el Reporte 01 GDO digital de documentos pendientes, retirando la selección de CRM 2011 del proyecto WebGestionDocumental, para eliminar la información desactualizada o inconsistente sobre los documentos pendientes, logrando un seguimiento confiable que favorezca el enrollment y la retención, proteja el revenue y el EBITDA, y reduzca las contingencias legales y normativas. | H13: =[2]Sheet1!H14 -> UPN | I13: =[2]Sheet1!I14 -> Ivan Olivares - VP Marketing y Comercial | ... AA13: =[2]Sheet1!AA14 -> 0.6
... A44: =IF([2]Sheet1!A45="","",[2]Sheet1!A45+399) | B44: =[2]Sheet1!B45 -> 0 | C44: =[2]Sheet1!C45 -> 0 | D44: =[2]Sheet1!D45 -> 0 | E44: =[2]Sheet1!E45 -> 0 | F44: =[2]Sheet1!F45 -> 0 | G44: =[2]Sheet1!G45 -> 0 | H44: =[2]Sheet1!H45 -> 0 | I44: =[2]Sheet1!I45 -> 0 | ... AA44: =[2]Sheet1!AA45 -> 0

Sheet BD 2
A1: Id | B1: Hora de inicio | C1: Hora de finalización | D1: Correo electrónico | E1: Nombre | F1: Título de la INICIATIVA | G1: Objetivo | H1: Institución | I1: VP del área solicitante | J1: Usuario solicitante del negocio | K1: Aprobación de la iniciativa por el VP o Director | L1: IT BP | M1: Fecha de entrega requerida | N1: Proyecto SPO | O1: Workstream del proyecto SPO | P1: ID SPO | Q1: Tipo de iniciativa | R1: Descripción del problema o desafío | S1: Situación deseada | T1: Procesos y áreas impactadas | U1: Usuarios beneficiados1 | V1: Pilar estratégico | W1: Forma parte de la estabilización de procesos SIS | X1: Beneficio cuantitativo (anual) | Y1: Beneficios cualitativos | Z1: Adjuntar ppt de la iniciativa | AA1: Puntaje sugerido
A2: 401 | B2: 46289.379 | C2: 46289.393 | D2: bruno.chiappe@laureate.pe | E2: Bruno Chiappe Vegas | F2: Automatización de carga de llamadas de Genesys a CRM Cibertec | G2: Necesitamos automatizar la carga de información de llamadas de Genesys hacia CRM Cibertec, para eliminar la ejecución manual y recurrente de cargas masivas que actualmente requiere intervención de especialistas y está sujeta a errores y retrasos, logrando disponer de la información oportunamente para el negocio, reducir la carga operativa del equipo TI y disminuir la necesidad de pases Express asociados a estas cargas. | H2: CIB | I2: Humberto Marotta - Tecnologías y transformación digital | J2: Katia Garvich | K2: https://educorpperu.sharepoint.com/sites/ITCS/Documentos%20compartidos/Aplicaciones/Microsoft%20Forms/REGISTRO%20DE%20INICIATIVAS%20-%20GESTI%C3%93N%20DE%20LA%20DEMANDA%20V3/Aprobaci%C3%B3n%20de%20la%20iniciativa%20por%20el%20VP%20del%20%C3%A1rea%20sol/RE_%20CIB%20Carga%20de%20datos%20de%20llamadas_Bruno%20Chiappe%20Vegas.pdf | L2: Bruno Chiappe | M2: 46326 | N2: No | O2: 0 | P2: 0 | Q2: Otro | R2: Actualmente, la información de llamadas proveniente de Genesys debe cargarse manualmente hacia CRM Cibertec al menos dos veces por semana. El procedimiento requiere intervención técnica directa sobre la base de datos y contempla múltiples actividades manuales, entre ellas ejecución de queries, importación de archivos, creación y eliminación de tablas temporales, validaciones, modificación de estructuras e índices y ejecución de procedimientos almacenados. Esto finalmente provoca la necesidad de gestionar pases Express para atender cargas masivas. | S2: Contar con un mecanismo automatizado que permita trasladar periódicamente la información de llamadas desde Genesys hacia CRM Cibertec, ejecutando las cargas y validaciones necesarias sin intervención manual recurrente y reduciendo significativamente los pases express. | T2: Proceso comercial / seguimiento de llamadas Áreas impactadas: - Command Center | U2: Administrativos | V2: Excelencia operativa | W2: No | X2: No cuantificado o S/0 | Y2: Reducción de errores asociados a cargas manuales. Mayor oportunidad y disponibilidad de la información para el negocio. Menor dependencia de especialistas para tareas operativas recurrentes. Liberación de capacidad del equipo TI para actividades de mayor valor. Reducción de pases Express asociados a cargas masivas. | Z2: https://educorpperu.sharepoint.com/sites/ITCS/_layouts/15/Doc.aspx?sourcedoc=%7BC67FA507-9566-45BD-8F12-A76BA4FD076A%7D&file=Manual%20de%20carga_Bruno%20Chiappe%20Vegas.docx&action=default&mobileredirect=true | AA2: =IFERROR(VLOOKUP(N2,'Criterios de priorización'!$E$3:$F$4,2,FALSE)*'Criterios de priorización'!$D$3,0)+IFERROR(VLOOKUP(Q2,'Criterios de priorización'!$E$5:$F$8,2,FALSE)*'Criterios de priorización'!$D$5,0)+IFERROR(VLOOKUP(X2,'Criterios de priorización'!$E$9:$F$12,2,FALSE)*'Criterios de priorización'!$D$9,0)+IFERROR(VLOOKUP(V2,'Criterios de priorización'!$E$13:$F$18,2,FALSE)*'Criterios de priorización'!$D$13,0)+IFERROR(VLOOKUP(U2,'Criterios de priorización'!$E$19:$F$22,2,FALSE)*'Criterios de priorización'!$D$19,0) -> 0.6
A3: 402 | B3: 46289.48 | C3: 46289.501 | D3: alejandra.beraun@laureate.pe | E3: Alejandra Beraun Ching | F3: Proyecto Cultura y Espacios | G3: Implementar una nueva aplicacion de reservas que mejore la gestión de asignación de salas y que esté correctamente distribuida para el personal administrativo. Para lo cual se está rediseñando el piso 26, de manera que la aplicación converse con el nuevo espacio. | H3: LAU | I3: Álvaro Valdez - VP Operaciones | J3: Alessandra Ravettino | K3: https://educorpperu.sharepoint.com/sites/ITCS/Documentos%20compartidos/Aplicaciones/Microsoft%20Forms/REGISTRO%20DE%20INICIATIVAS%20-%20GESTI%C3%93N%20DE%20LA%20DEMANDA%20V3/Aprobaci%C3%B3n%20de%20la%20iniciativa%20por%20el%20VP%20del%20%C3%A1rea%20sol/VB%20Alvaro%20Valdez%20-%20Archie_Alejandra%20Beraun%20Chi.pdf | L3: Franco Vera | M3: 46325 | N3: No | O3: 0 | P3: 0 | Q3: Otro | R3: Se contará con el proveedor actual de Communal hasta el 30/09 y se está buscando otra alternativa de app de reserva de espacios para el equipo central. | S3: Que la aplicación cumpla nuestras expectativas y nos permite distribuir adecuadamente todos los espacios de LCT en los que se encuentran nuestros colaboradores (salas de reuniones y estacionamiento), mejorando la experiencia del colaborador que asiste a sede | T3: Todos los equipos que asisten de manera presencial a LCT Proceso de reserva de espacios (salas y estacionamientos) | U3: Administrativos | V3: Experiencia | W3: No | X3: No cuantificado o S/0 | Y3: Mejora la experiencia del colaborador que asiste a sede (incluye VPs, visitas, entre otros) | Z3: https://educorpperu.sharepoint.com/sites/ITCS/_layouts/15/Doc.aspx?sourcedoc=%7B56FF1655-E73D-422C-A2B6-33849D7CB5A8%7D&file=Gesti%C3%B3n%20de%20iniciativas%20-%20Archie%201_Alejandra%20Beraun%20Chi.pptx&action=edit&mobileredirect=true | AA3: =IFERROR(VLOOKUP(N3,'Criterios de priorización'!$E$3:$F$4,2,FALSE)*'Criterios de priorización'!$D$3,0)+IFERROR(VLOOKUP(Q3,'Criterios de priorización'!$E$5:$F$8,2,FALSE)*'Criterios de priorización'!$D$5,0)+IFERROR(VLOOKUP(X3,'Criterios de priorización'!$E$9:$F$12,2,FALSE)*'Criterios de priorización'!$D$9,0)+IFERROR(VLOOKUP(V3,'Criterios de priorización'!$E$13:$F$18,2,FALSE)*'Criterios de priorización'!$D$13,0)+IFERROR(VLOOKUP(U3,'Criterios de priorización'!$E$19:$F$22,2,FALSE)*'Criterios de priorización'!$D$19,0) -> 0.7
A4: 403 | B4: 46289.51 | C4: 46289.537 | D4: suly.kong@upn.edu.pe | E4: Suly Kong Paredes | F4: La Defensoría tiene sobrecarga por atención unipersonal y desinformación de los usuarios, quienes acuden de forma presencial por trámites ajenos a sus funciones. La falta de un filtro digital previo genera atenciones prolongadas y dificulta organizar los expedientes con sustento desde el inicio. | G4: Proporcionar a la comunidad universitaria (estudiantes, egresados, docentes y colaboradores) un canal digital estructurado, accesible y confidencial para canalizar petitorios, consultas y denuncias, estandarizando los requisitos desde el origen para optimizar los tiempos de respuesta y asegurar la correcta derivación institucional. | H4: UPN | I4: Martín Santana - Rectorado UPN | J4: Suly Kong Paredes | K4: https://educorpperu.sharepoint.com/sites/ITCS/Documentos%20compartidos/Aplicaciones/Microsoft%20Forms/REGISTRO%20DE%20INICIATIVAS%20-%20GESTI%C3%93N%20DE%20LA%20DEMANDA%20V3/Aprobaci%C3%B3n%20de%20la%20iniciativa%20por%20el%20VP%20del%20%C3%A1rea%20sol/correo%20de%20aprobaci%C3%B3n%20Alex%20Rueda_Suly%20Kong%20Paredes.pdf | L4: Gerson Vereau | M4: 46307 | N4: No | O4: 0 | P4: 0 | Q4: Regulatoria | R4: 7.1 Sobrecarga operativa por atención unipersonal frente a alta demanda:_x000B_La Defensoría Universitaria cuenta con una sola persona a cargo para atender un volumen desbordante de casos de toda la comunidad universitaria, lo que genera cuellos de botella y dificulta el seguimiento oportuno de cada expediente 7.2 Tiempos excesivos en atención presencial poco estructurada:_x000B_Los estudiantes acuden de manera presencial y tardan demasiado tiempo en exponer sus situaciones de forma dispersa, sin tener claridad previa de lo que realmente necesitan ni de qué derecho solicitan tutelar, consumiendo valiosas horas de atención individual. 7.3 Alta recepción de casos que no son de competencia de la Defensoría:_x000B_La gran mayoría de usuarios desconoce las funciones de esta instancia y acude por temas que corresponden a Reclamos, secretarías académicas o comisiones disciplinarias/hostigamiento sexual. Esto convierte a la Defensoría en una mesa de orientación básica, perdiendo tiempo crítico en derivar casos en lugar de atender los expedientes que sí le competen. 7.4 Carencia de un filtro previo y expediente ordenado:_x000B_Al no existir un canal digital previo que filtre la admisibilidad y obligue al estudiante a definir su solicitud (consulta, petitorio o denuncia) con sustentos ordenados desde el inicio, se invierten extensas jornadas en recopilar información dispersa y orientar casos improcedentes. _x000B_ | S4: El nuevo formulario filtra casos fuera de competencia, guía al estudiante para tipificar su trámite y exige evidencias obligatorias para evitar reprocesos. Esto permite a la DU evaluar y priorizar cada expediente en una base centralizada, programando citas presenciales solo cuando realmente se amerite. | T4: Contacto UPN | U4: Todos | V4: Excelencia operativa | W4: No | X4: No cuantificado o S/0 | Y4: Beneficios para el usuario: Asistido (Autoayuda): Guía paso a paso con ejemplos claros, facilitando la distinción inmediata entre consulta, petitorio o denuncia. Ahorro de tiempo: Trámite 100% digital 24/7 desde cualquier campus o modalidad. Carga de pruebas ordenada: Permite adjuntar evidencias de forma secuencial o sustentar petitorios Atención inclusiva y prioritaria: Identificación reservada de situaciones de vulnerabilidad (salud, discapacidad o NEE) para activar ajustes razonables inmediatos. Claridad en la competencia: Delimita los casos que corresponden a la Defensoría frente a otras áreas (como Reclamos u Hostigamiento Sexual), evitando derivaciones erróneas. Trazabilidad y respaldo formal: Genera un cargo de recepción con fecha, hora para control inmediato del usuario y DU | Z4: https://educorpperu.sharepoint.com/sites/ITCS/_layouts/15/Doc.aspx?sourcedoc=%7BA37B411B-E6E0-4B17-AE31-CEC2497430BD%7D&file=PPT%20Implementaci%C3%B3n%20de%20formulario%20DU_Suly%20Kong%20Paredes.pptx&action=edit&mobileredirect=true; https://educorpperu.sharepoint.com/sites/ITCS/_layouts/15/Doc.aspx?sourcedoc=%7B764A2D38-08A7-4D87-B1C4-B9607E08DAD5%7D&file=Copia%20de%20Proyecto%20Formulario%20SIPOC_Suly%20Kong%20Paredes.xlsx&action=default&mobileredirect=true; https://educorpperu.sharepoint.com/sites/ITCS/_layouts/15/Doc.aspx?sourcedoc=%7B17EE13F9-F683-4F1D-9DAC-CC880ED08A74%7D&file=Formulario%20de%20Atenci%C3%B3n%20DU%202026%20vf_Suly%20Kong%20Paredes.docx&action=default&mobileredirect=true | AA4: =IFERROR(VLOOKUP(N4,'Criterios de priorización'!$E$3:$F$4,2,FALSE)*'Criterios de priorización'!$D$3,0)+IFERROR(VLOOKUP(Q4,'Criterios de priorización'!$E$5:$F$8,2,FALSE)*'Criterios de priorización'!$D$5,0)+IFERROR(VLOOKUP(X4,'Criterios de priorización'!$E$9:$F$12,2,FALSE)*'Criterios de priorización'!$D$9,0)+IFERROR(VLOOKUP(V4,'Criterios de priorización'!$E$13:$F$18,2,FALSE)*'Criterios de priorización'!$D$13,0)+IFERROR(VLOOKUP(U4,'Criterios de priorización'!$E$19:$F$22,2,FALSE)*'Criterios de priorización'!$D$19,0) -> 2.7
A5: 404 | B5: 46290.496 | C5: 46290.509 | D5: brenda.maguina@laureate.pe | E5: Brenda Michelle Maguiña Delgadillo | F5: Implementación de Reloj Fisico-Personal Fiscalizado Presencial. | G5: Necesitamos asegurar que el colaborador deberá realizar su marcación al llegar físicamente a las instalaciones de todas las instituciones inlcuyendo LCT. El registro quedará asociado al marcador y será integrado con el sistema HCM, con veracidad. | H5: CORP | I5: Tairi Ruillier- VP Personas y Cultura | J5: Peter Casas Aranguren | K5: https://educorpperu.sharepoint.com/sites/ITCS/Documentos%20compartidos/Aplicaciones/Microsoft%20Forms/REGISTRO%20DE%20INICIATIVAS%20-%20GESTI%C3%93N%20DE%20LA%20DEMANDA%20V3/Aprobaci%C3%B3n%20de%20la%20iniciativa%20por%20el%20VP%20del%20%C3%A1rea%20sol/VB%20Alfredo_Brenda%20Michelle%20Magu.pdf | L5: Franco Vera | M5: 46418 | N5: No | O5: 0 | P5: 0 | Q5: Otro | R5: Actualmente, un colaborador puede registrar su asistencia desde su dispositivo móvil antes de llegar físicamente a su centro de labores. El sistema puede mostrar una hora de ingreso correcta o incluso puntual, aunque la llegada real haya ocurrido después. Cuando existe una discrepancia, se requiere revisar las cámaras para comprobar la hora efectiva de llegada. | S5: La propuesta consiste en instalar marcadores físicos en puntos estratégicos del campus, principalmente en accesos y zonas de ingreso de colaboradores presenciales. El colaborador deberá realizar su marcación al llegar físicamente a las instalaciones. El registro quedará asociado al marcador y será integrado con el sistema HCM. | T5: Todas las areas que tengan personal fiscalizado- con modalidad presencial. | U5: Administrativos | V5: Experiencia | W5: No | X5: No cuantificado o S/0 | Y5: Veracidad de información al registrar su marcación de ingreso y salida al llegar físicamente a las instalaciones de su centro de labores. | Z5: https://educorpperu.sharepoint.com/sites/ITCS/_layouts/15/Doc.aspx?sourcedoc=%7BF44B3260-D237-425E-93E1-0F2ADAD667BC%7D&file=VF.%20Gesti%C3%B3n%20de%20iniciativas%20-%20Proceso%20y%20regist_Brenda%20Michelle%20Magu.pptx&action=edit&mobileredirect=true | AA5: =IFERROR(VLOOKUP(N5,'Criterios de priorización'!$E$3:$F$4,2,FALSE)*'Criterios de priorización'!$D$3,0)+IFERROR(VLOOKUP(Q5,'Criterios de priorización'!$E$5:$F$8,2,FALSE)*'Criterios de priorización'!$D$5,0)+IFERROR(VLOOKUP(X5,'Criterios de priorización'!$E$9:$F$12,2,FALSE)*'Criterios de priorización'!$D$9,0)+IFERROR(VLOOKUP(V5,'Criterios de priorización'!$E$13:$F$18,2,FALSE)*'Criterios de priorización'!$D$13,0)+IFERROR(VLOOKUP(U5,'Criterios de priorización'!$E$19:$F$22,2,FALSE)*'Criterios de priorización'!$D$19,0) -> 0.7
A6: 405 | B6: 46290.505 | C6: 46290.536 | D6: miguel.puccio@upn.edu.pe | E6: Miguel Puccio Wendorff | F6: Configuracion de apertura de beneficios de admisión | G6: - Modificación del calculo sobre el beneficio mayor - Recalculo sobre más de una línea de beneficio - Visualización de los distintos beneficios que se ofrece a alumno en las boletas, detallando cada beneficio en una linea independiente - Creación de tabla intermedia para homologación de categorías | H6: UPC | I6: Alex Pendavis - VP Finanzas | J6: Miguel Puccio Wendorff | K6: https://educorpperu.sharepoint.com/sites/ITCS/Documentos%20compartidos/Aplicaciones/Microsoft%20Forms/REGISTRO%20DE%20INICIATIVAS%20-%20GESTI%C3%93N%20DE%20LA%20DEMANDA%20V3/Aprobaci%C3%B3n%20de%20la%20iniciativa%20por%20el%20VP%20del%20%C3%A1rea%20sol/VB%20Miguel%20Bandach_Cambio%20de%20precios_Miguel%20Puccio%20Wendor.pdf | L6: Gerson Vereau | M6: 46349 | N6: No | O6: 0 | P6: 0 | Q6: Otro | R6: Problema de visualizacion de beneficios. Hoy se está sumando todos los beneficios en una sola línea generando confusión y nula trazabilidad. Existen hoy en día más de 41k combinaciones de descuentos (Ids). | S6: Mayor transparencia y trazabilidad de los beneficios otorgados. Reducción del número de Ids de beneficios para simplificar el proceso de venta. | T6: Admisión / Ventas / Facturación / Becas / Planeamiento / Experiencia / Retención / Contabilidad / Control Interno / Sistemas | U6: Todos | V6: Excelencia operativa | W6: No | X6: No cuantificado o S/0 | Y6: - Minimización de errores al facturar - Mayor trazabilidad de los beneficios - Mayor transparencia para el estudiante - Eficiencia operativa al no contar con lista de IDs de beneficios crecientes (>41k) | Z6: https://educorpperu.sharepoint.com/sites/ITCS/_layouts/15/Doc.aspx?sourcedoc=%7BD56CE3C0-AFCD-45CD-89AE-0194B74B5556%7D&file=Gesti%C3%B3n%20de%20iniciativas%20-%20Proceso%20y%20registro%203_Miguel%20Puccio%20Wendor.pptx&action=edit&mobileredirect=true | AA6: =IFERROR(VLOOKUP(N6,'Criterios de priorización'!$E$3:$F$4,2,FALSE)*'Criterios de priorización'!$D$3,0)+IFERROR(VLOOKUP(Q6,'Criterios de priorización'!$E$5:$F$8,2,FALSE)*'Criterios de priorización'!$D$5,0)+IFERROR(VLOOKUP(X6,'Criterios de priorización'!$E$9:$F$12,2,FALSE)*'Criterios de priorización'!$D$9,0)+IFERROR(VLOOKUP(V6,'Criterios de priorización'!$E$13:$F$18,2,FALSE)*'Criterios de priorización'!$D$13,0)+IFERROR(VLOOKUP(U6,'Criterios de priorización'!$E$19:$F$22,2,FALSE)*'Criterios de priorización'!$D$19,0) -> 1.2
A7: 406 | B7: 46291.414 | C7: 46291.449 | D7: franco.vera@laureate.pe | E7: Franco Manuel Vera Sanchez | F7: LEAN+IA: CALIDAD | G7: Estimar componentes fuera de desarrollo (licencias, almacenamiento, integraciones, etc) para repotenciar, agilizar, simplificar y estandarizar el flujo end-to-end de la gestión integral de aseguramiento de la calidad, apalancando en la Inteligencia Artificial y otras tecnologías como aliadas estratégicas, de tal forma que logremos liberar al equipo de las carga operativa y manual para que puedan enfocar su verdadero talento en actividades de alto valor, análisis estratégico y mejora continua, repotenciando su rol. | H7: CORP | I7: Joaquín Uribarri - VP Academia CIB | J7: Manuel Cortes Fontcuberta | K7: https://educorpperu.sharepoint.com/sites/ITCS/Documentos%20compartidos/Aplicaciones/Microsoft%20Forms/REGISTRO%20DE%20INICIATIVAS%20-%20GESTI%C3%93N%20DE%20LA%20DEMANDA%20V3/Aprobaci%C3%B3n%20de%20la%20iniciativa%20por%20el%20VP%20del%20%C3%A1rea%20sol/VB%20Manuel%20Cortes_Franco%20Manuel%20Vera%20S.pdf | L7: Franco Vera | M7: 46304 | N7: Sí | O7: Digital & IA | P7: 78088 | Q7: Otro | R7: Demasiada carga manual y operativa por parte de los equipos de aseguramiento de la calidad. | S7: Repotenciar, agilizar, simplificar y estandarizar el flujo end-to-end de la gestión integral de aseguramiento de la calidad, apalancando en la Inteligencia Artificial y otras tecnologías como aliadas estratégicas. | T7: Aseguramiento de la Calidad UPN-UPC y todas las áreas que comparten información. | U7: Administrativos | V7: Excelencia operativa | W7: No | X7: No cuantificado o S/0 | Y7: Automatizar procesos que pueden incurrir en errores manuales y entregas fuera del SLA, incluso para entidades auditoras externas. | Z7: https://educorpperu.sharepoint.com/sites/ITCS/_layouts/15/Doc.aspx?sourcedoc=%7B6448B771-797F-4396-B61E-9D4823DF0473%7D&file=Gesti%C3%B3n%20de%20iniciativas%20-%20LEAN%2BIA%20CALIDAD_Franco%20Manuel%20Vera%20S.pptx&action=edit&mobileredirect=true; https://educorpperu.sharepoint.com/sites/ITCS/Documentos%20compartidos/Aplicaciones/Microsoft%20Forms/REGISTRO%20DE%20INICIATIVAS%20-%20GESTI%C3%93N%20DE%20LA%20DEMANDA%20V3/Adjuntar%20ppt%20de%20la%20iniciativa/LEAN%20+%20IA%20Aseg.%20Calidad_TOBE_Franco%20Manuel%20Vera%20S.png | AA7: =IFERROR(VLOOKUP(N7,'Criterios de priorización'!$E$3:$F$4,2,FALSE)*'Criterios de priorización'!$D$3,0)+IFERROR(VLOOKUP(Q7,'Criterios de priorización'!$E$5:$F$8,2,FALSE)*'Criterios de priorización'!$D$5,0)+IFERROR(VLOOKUP(X7,'Criterios de priorización'!$E$9:$F$12,2,FALSE)*'Criterios de priorización'!$D$9,0)+IFERROR(VLOOKUP(V7,'Criterios de priorización'!$E$13:$F$18,2,FALSE)*'Criterios de priorización'!$D$13,0)+IFERROR(VLOOKUP(U7,'Criterios de priorización'!$E$19:$F$22,2,FALSE)*'Criterios de priorización'!$D$19,0) -> 0.6
A8: 407 | B8: 46292.883 | C8: 46292.893 | D8: percy.romero@laureate.pe | E8: Percy Romero Vegas | F8: APLICATIVO DE CONCILIACION MEDIOS DE PAGO - CIBERTEC | G8: Implementar una herramienta de conciliación automática de medios de pago, que permita integrar y validar diariamente las transacciones provenientes de BCP, Interbank, Scotiabank, BBVA y Niubiz, u otro medio de pago comparándolas contra los registos del sistema Spring Comercial de CIB (tal como lo tiene UPC). | H8: CIB | I8: Alex Pendavis - VP Finanzas | J8: Medios de Pago | K8: https://educorpperu.sharepoint.com/sites/ITCS/Documentos%20compartidos/Aplicaciones/Microsoft%20Forms/REGISTRO%20DE%20INICIATIVAS%20-%20GESTI%C3%93N%20DE%20LA%20DEMANDA%20V3/Aprobaci%C3%B3n%20de%20la%20iniciativa%20por%20el%20VP%20del%20%C3%A1rea%20sol/APROBACION%20DIRECTOR_Percy%20Romero%20Vegas.pdf | L8: Franco Vera | M8: 46321 | N8: No | O8: 0 | P8: 0 | Q8: Otro | R8: Situación Actual: 1.- CIB opera con 5 medios de pago: BCP, Interbank, Scotiabank, BBVA y Niubiz (intranet del alumno). 2.- No existe un proceso de conciliación diario automatizado. 3.- La validación de ingresos se realiza de forma reactiva, principalmente por reclamos de alumnos o consultas de áreas internas (Contabilidad. Comercial, Admisión, Cobranzas). | S8: Implementar una herramienta de conciliación automática de medios de pago, que permita integrar y validar diariamente las transacciones provenientes de BCP, Interbank, Scotiabank, BBVA y Niubiz, comparándolas contra los registros del sistema Spring Comercial de CIB (tal como lo tiene UPC). | T8: Medios de Pago, Cobranzas, Contabilidad, Admisión, Ventas, Coemrcial. | U8: Todos | V8: Experiencia | W8: No | X8: Mayor a S/500,000.00 | Y8: Reducción, Riesgo Financiero, Riesgo Operativo, Riesgo Reputacional. | Z8: https://educorpperu.sharepoint.com/sites/ITCS/_layouts/15/Doc.aspx?sourcedoc=%7BF226C316-9D65-443A-AF7A-C4AF217611D6%7D&file=1.-%20Solicitud%20de%20requerimientos%20-%20%20Aplicativo_Percy%20Romero%20Vegas.pptx&action=edit&mobileredirect=true | AA8: =IFERROR(VLOOKUP(N8,'Criterios de priorización'!$E$3:$F$4,2,FALSE)*'Criterios de priorización'!$D$3,0)+IFERROR(VLOOKUP(Q8,'Criterios de priorización'!$E$5:$F$8,2,FALSE)*'Criterios de priorización'!$D$5,0)+IFERROR(VLOOKUP(X8,'Criterios de priorización'!$E$9:$F$12,2,FALSE)*'Criterios de priorización'!$D$9,0)+IFERROR(VLOOKUP(V8,'Criterios de priorización'!$E$13:$F$18,2,FALSE)*'Criterios de priorización'!$D$13,0)+IFERROR(VLOOKUP(U8,'Criterios de priorización'!$E$19:$F$22,2,FALSE)*'Criterios de priorización'!$D$19,0) -> 1.9
A9: 408 | B9: 46293.341 | C9: 46293.352 | D9: luis.calderon@laureate.pe | E9: Luis Calderon Rodriguez | F9: Upgrade y modernización de Jobs Batch UPN | G9: Necesitamos actualizar y modernizar los jobs batch de UPN, para habilitar su migración y distribución en la nueva infraestructura, logrando reducir riesgos tecnológicos y mejorar la estabilidad y continuidad operativa de los procesos que soportan. | H9: UPN | I9: Humberto Marotta - Tecnologías y transformación digital | J9: Christian Quiroz | K9: https://educorpperu.sharepoint.com/sites/ITCS/_layouts/15/Doc.aspx?sourcedoc=%7B4CA4154C-D0E3-4B58-A3FB-440A7E50A586%7D&file=Correo%20de%20aprobaci%C3%B3n%20-%20Humberto_Luis%20Calderon%20Rodrig.docx&action=default&mobileredirect=true | L9: Gerson Vereau | M9: 46311 | N9: No | O9: 0 | P9: 0 | Q9: ITSM | R9: Los jobs batch de UPN presentan componentes y frameworks obsoletos que limitan su migración a la nueva infraestructura, manteniendo la concentración de procesamiento en servidores actuales y generando riesgos de saturación, indisponibilidad y continuidad operativa. De no implementarse la iniciativa, los jobs deberán continuar operando temporalmente en la infraestructura actual, manteniendo estos riesgos. | S9: Contar con los jobs batch actualizados y compatibles con la nueva infraestructura, permitiendo distribuir su ejecución entre los nuevos servidores, reducir la concentración de carga y mejorar su estabilidad, operación y mantenimiento. | T9: Áreas: TI – Aplicaciones e Infraestructura Procesos: Procesos de negocio de UPN soportados por los jobs batch involucrados en la iniciativa. | U9: Administrativos | V9: Excelencia operativa | W9: No | X9: No cuantificado o S/0 | Y9: Mayor estabilidad y continuidad operativa de los procesos batch, reducción del riesgo de saturación y puntos únicos de falla, actualización de componentes obsoletos y reducción de incidencias y tickets asociados a fallas de los jobs. | Z9: https://educorpperu.sharepoint.com/sites/ITCS/_layouts/15/Doc.aspx?sourcedoc=%7B19CFF8EC-55FE-40DF-90A8-70B504935AD4%7D&file=Gesti%C3%B3n%20de%20iniciativas%20-%20Jobs%20UPN_Luis%20Calderon%20Rodrig.pptx&action=edit&mobileredirect=true | AA9: =IFERROR(VLOOKUP(N9,'Criterios de priorización'!$E$3:$F$4,2,FALSE)*'Criterios de priorización'!$D$3,0)+IFERROR(VLOOKUP(Q9,'Criterios de priorización'!$E$5:$F$8,2,FALSE)*'Criterios de priorización'!$D$5,0)+IFERROR(VLOOKUP(X9,'Criterios de priorización'!$E$9:$F$12,2,FALSE)*'Criterios de priorización'!$D$9,0)+IFERROR(VLOOKUP(V9,'Criterios de priorización'!$E$13:$F$18,2,FALSE)*'Criterios de priorización'!$D$13,0)+IFERROR(VLOOKUP(U9,'Criterios de priorización'!$E$19:$F$22,2,FALSE)*'Criterios de priorización'!$D$19,0) -> 1.5
A10: 409 | B10: 46294.377 | C10: 46294.38 | D10: angela.lucano@laureate.pe | E10: Angela Lucano Carranza | F10: Adecuación del Reporte de Retiro de Oficio UPC a la nueva normativa académica 2026 | G10: Necesitamos adecuar el reporte de Retiro de Oficio vigente para alinearlo con la nueva normativa académica UPC, logrando una identificación automática, precisa y oportuna de estudiantes sujetos a retiro de oficio, asegurando el cumplimiento regulatorio y la continuidad del proceso académico dentro de los plazos establecidos para noviembre 2026. | H10: UPC | I10: Milagros Morgan - Rectorado UPC | J10: Miguel Chang | K10: https://educorpperu.sharepoint.com/sites/ITCS/Documentos%20compartidos/Aplicaciones/Microsoft%20Forms/REGISTRO%20DE%20INICIATIVAS%20-%20GESTI%C3%93N%20DE%20LA%20DEMANDA%20V3/Aprobaci%C3%B3n%20de%20la%20iniciativa%20por%20el%20VP%20del%20%C3%A1rea%20sol/Adecuaci%C3%B3n%20del%20Reporte%20de%20Retiro%20de%20Oficio%20UP_Angela%20Lucano%20Carran.pdf | L10: Ángela Lucano | M10: 46328 | N10: No | O10: 0 | P10: 0 | Q10: Regulatoria | R10: En marzo de 2026 se aprobó una nueva política de Retiro de Oficio que modifica los criterios utilizados para identificar estudiantes sujetos a esta medida académica. Actualmente, el reporte SOX-Compliance denominado "Reporte Preliminar de Retiro de Oficio - SOX_UPC_007" fue construido bajo la normativa anterior y no contempla las nuevas validaciones requeridas. | S10: Contar con un reporte automatizado y disponible que: Incorpore la modalidad de estudio del alumno (Presencial, Semipresencial o A Distancia). Evalúe asistencia menor al 10% para alumnos presenciales y semipresenciales. Evalúe falta de conexión al Aula Virtual para alumnos a distancia. Valide el no pago de la primera boleta. Mantenga las validaciones académicas vigentes de notas. Sea utilizado de manera oficial para la ejecución del proceso de Retiro de Oficio del ciclo académico correspondiente. Cumpla los lineamientos SOX y de Compliance. | T10: Gestión académica. Retiro de oficio. Control de matrícula. Seguimiento de asistencia. Seguimiento financiero de estudiantes. Auditoría y cumplimiento SOX. | U10: Administrativos | V10: Excelencia operativa | W10: No | X10: Menor a S/100,000.00 | Y10: Cumplimiento regulatorio, reducción de riesgo SOX y eficiencia operativa. | Z10: https://educorpperu.sharepoint.com/sites/ITCS/_layouts/15/Doc.aspx?sourcedoc=%7BF5F7A701-FCD7-4860-9BB9-53DF574BB443%7D&file=Gesti%C3%B3n%20de%20iniciativas%20-%20RETIRO%20DE%20OFICIO%20DOA_Angela%20Lucano%20Carran.pptx&action=edit&mobileredirect=true | AA10: =IFERROR(VLOOKUP(N10,'Criterios de priorización'!$E$3:$F$4,2,FALSE)*'Criterios de priorización'!$D$3,0)+IFERROR(VLOOKUP(Q10,'Criterios de priorización'!$E$5:$F$8,2,FALSE)*'Criterios de priorización'!$D$5,0)+IFERROR(VLOOKUP(X10,'Criterios de priorización'!$E$9:$F$12,2,FALSE)*'Criterios de priorización'!$D$9,0)+IFERROR(VLOOKUP(V10,'Criterios de priorización'!$E$13:$F$18,2,FALSE)*'Criterios de priorización'!$D$13,0)+IFERROR(VLOOKUP(U10,'Criterios de priorización'!$E$19:$F$22,2,FALSE)*'Criterios de priorización'!$D$19,0) -> 2.25
A11: 410 | B11: 46294.694 | C11: 46294.705 | D11: angela.lucano@laureate.pe | E11: Angela Lucano Carranza | F11: UPC: Adecuación de sistemas periféricos para soportar las nuevas mallas curriculares 2027 | G11: Necesitamos adecuar los sistemas periféricos que consumen información académica de Banner para soportar correctamente el versionamiento de mallas curriculares, logrando que estudiantes, docentes y áreas administrativas visualicen información académica correcta y consistente en todos los sistemas. | H11: UPC | I11: Milagros Morgan - Rectorado UPC | J11: Mónica Zavala | K11: https://educorpperu.sharepoint.com/sites/ITCS/_layouts/15/Doc.aspx?sourcedoc=%7BB1AF7D21-41BE-451D-90A7-D1C662B3DC9C%7D&file=Resumen%20reuni%C3%B3n%20-%20Proyecto%20mallas%202027_Angela%20Lucano%20Carran.docx&action=default&mobileredirect=true | L11: Ángela Lucano | M11: 46416 | N11: No | O11: 0 | P11: 0 | Q11: Regulatoria | R11: Actualmente, los cambios realizados en las mallas curriculares son gestionados por Banner; sin embargo, varios sistemas que consumen esta información no están preparados para reconocer las distintas versiones de cursos y mallas. Esto puede generar información incorrecta, registros duplicados o diferencias entre sistemas al momento de consultar datos académicos. | S11: Contar con sistemas alineados al modelo académico de Banner, capaces de identificar y mostrar la versión correcta de cursos y mallas según corresponda a cada estudiante, garantizando información consistente en todos los canales y procesos académicos. | T11: Consulta de cursos y mallas curriculares. Seguimiento del avance académico. Reportería académica y de gestión. Integraciones entre sistemas. Atención de trámites y consultas académicas. | U11: Todos | V11: Excelencia operativa | W11: No | X11: No cuantificado o S/0 | Y11: Reducción de incidencias por información académica incorrecta. Disminución del tiempo dedicado a validaciones y correcciones manuales. Eliminación de registros duplicados en consultas y reportes. Mayor confianza en la información mostrada a estudiantes y docentes. Capacidad de implementar futuras actualizaciones curriculares con menor esfuerzo. Consistencia de la información entre todos los sistemas institucionales. | Z11: https://educorpperu.sharepoint.com/sites/ITCS/_layouts/15/Doc.aspx?sourcedoc=%7BEF9FEB94-34ED-4AAA-BBD4-87AEA8C067DC%7D&file=Documento%20Funcional%20implementaci%C3%B3n%20de%20malla%202_Angela%20Lucano%20Carran.docx&action=default&mobileredirect=true | AA11: =IFERROR(VLOOKUP(N11,'Criterios de priorización'!$E$3:$F$4,2,FALSE)*'Criterios de priorización'!$D$3,0)+IFERROR(VLOOKUP(Q11,'Criterios de priorización'!$E$5:$F$8,2,FALSE)*'Criterios de priorización'!$D$5,0)+IFERROR(VLOOKUP(X11,'Criterios de priorización'!$E$9:$F$12,2,FALSE)*'Criterios de priorización'!$D$9,0)+IFERROR(VLOOKUP(V11,'Criterios de priorización'!$E$13:$F$18,2,FALSE)*'Criterios de priorización'!$D$13,0)+IFERROR(VLOOKUP(U11,'Criterios de priorización'!$E$19:$F$22,2,FALSE)*'Criterios de priorización'!$D$19,0) -> 2.7
